Workbook

Sheet All 17 saved engineering invest
A1: All 17 saved engineering investigations
A2: Observed engineering evidence — 2026-10-12 · Main Scenario
A4: Variable / dimension | B4: Engineering target | C4: Engineering outcome | D4: Engineering inference model | E4: Engineering run day | F4: Engineering input tokens | G4: Engineering output tokens | H4: Engineering elapsed seconds | I4: Engineering response-header gateway accounting USD | J4: Engineering header coverage | K4: Engineering source SHA | L4: Engineering original evidence files | M4: Engineering inference model coverage | N4: Engineering transport token coverage | O4: Engineering record count | P4: Engineering accounted header record
A5: 66349e06-fc57-4de9-836f-b0a0d7ca0584 | B5: ="buggy" -> buggy | C5: ="inconclusive" -> inconclusive | D5: ="Unknown" -> Unknown | E5: ="2026-10-11" -> 2026-10-11 | F5: ="" | G5: ="" | H5: =3.43 -> 3.43 | I5: ="" | J5: ="Unknown" -> Unknown | K5: ="Unknown" -> Unknown | L5: ="66349e06-fc57-4de9-836f-b0a0d7ca0584: model-usage.json; verification.json; control-verification.json; report.md" -> 66349e06-fc57-4de9-836f-b0a0d7ca0584: model-usage.json; verification.json; control-verification.json; report.md | M5: ="Unknown" -> Unknown | N5: ="Unknown/Unknown" -> Unknown/Unknown | O5: =1 -> 1 | P5: =IF('All 17 saved engineering invest'!I5="",0,1) -> 0
A6: e07bdfa3-c839-4e68-b784-640244403b2c | B6: ="buggy" -> buggy | C6: ="inconclusive" -> inconclusive | D6: ="Claude Sonnet 4.6" -> Claude Sonnet 4.6 | E6: ="2026-10-12" -> 2026-10-12 | F6: =11259 -> 11259 | G6: =391 -> 391 | H6: =15.818 -> 15.818 | I6: ="" | J6: ="Unknown" -> Unknown | K6: ="Unknown" -> Unknown | L6: ="e07bdfa3-c839-4e68-b784-640244403b2c: model-usage.json; verification.json; control-verification.json; report.md" -> e07bdfa3-c839-4e68-b784-640244403b2c: model-usage.json; verification.json; control-verification.json; report.md | M6: ="Claude Sonnet 4.6" -> Claude Sonnet 4.6 | N6: ="All recorded transport responses, including invalid responses" -> All recorded transport responses, including invalid responses | O6: =1 -> 1 | P6: =IF('All 17 saved engineering invest'!I6="",0,1) -> 0
A7: 6992fe74-3395-430a-95ab-d73c207d70b6 | B7: ="buggy" -> buggy | C7: ="inconclusive" -> inconclusive | D7: ="Claude Sonnet 4.6" -> Claude Sonnet 4.6 | E7: ="2026-10-12" -> 2026-10-12 | F7: =8635 -> 8635 | G7: =328 -> 328 | H7: =10.446 -> 10.446 | I7: ="" | J7: ="Unknown" -> Unknown | K7: ="Unknown" -> Unknown | L7: ="6992fe74-3395-430a-95ab-d73c207d70b6: model-usage.json; verification.json; control-verification.json; report.md" -> 6992fe74-3395-430a-95ab-d73c207d70b6: model-usage.json; verification.json; control-verification.json; report.md | M7: ="Claude Sonnet 4.6" -> Claude Sonnet 4.6 | N7: ="All recorded transport responses, including invalid responses" -> All recorded transport responses, including invalid responses | O7: =1 -> 1 | P7: =IF('All 17 saved engineering invest'!I7="",0,1) -> 0
A8: 7e60e53a-1a02-4f81-918d-24649030fae0 | B8: ="buggy" -> buggy | C8: ="inconclusive" -> inconclusive | D8: ="Claude Sonnet 4.6" -> Claude Sonnet 4.6 | E8: ="2026-10-12" -> 2026-10-12 | F8: =8530 -> 8530 | G8: =310 -> 310 | H8: =10.59 -> 10.59 | I8: ="" | J8: ="Unknown" -> Unknown | K8: ="Unknown" -> Unknown | L8: ="7e60e53a-1a02-4f81-918d-24649030fae0: model-usage.json; verification.json; control-verification.json; report.md" -> 7e60e53a-1a02-4f81-918d-24649030fae0: model-usage.json; verification.json; control-verification.json; report.md | M8: ="Claude Sonnet 4.6" -> Claude Sonnet 4.6 | N8: ="All recorded transport responses, including invalid responses" -> All recorded transport responses, including invalid responses | O8: =1 -> 1 | P8: =IF('All 17 saved engineering invest'!I8="",0,1) -> 0
A9: 39b9bed4-fca9-4884-a7b9-3035fc860685 | B9: ="fixed" -> fixed | C9: ="inconclusive" -> inconclusive | D9: ="Claude Sonnet 4.6" -> Claude Sonnet 4.6 | E9: ="2026-10-12" -> 2026-10-12 | F9: =8592 -> 8592 | G9: =268 -> 268 | H9: =10.073 -> 10.073 | I9: ="" | J9: ="Unknown" -> Unknown | K9: ="Unknown" -> Unknown | L9: ="39b9bed4-fca9-4884-a7b9-3035fc860685: model-usage.json; verification.json; control-verification.json; report.md" -> 39b9bed4-fca9-4884-a7b9-3035fc860685: model-usage.json; verification.json; control-verification.json; report.md | M9: ="Claude Sonnet 4.6" -> Claude Sonnet 4.6 | N9: ="All recorded transport responses, including invalid responses" -> All recorded transport responses, including invalid responses | O9: =1 -> 1 | P9: =IF('All 17 saved engineering invest'!I9="",0,1) -> 0
A10: 70582bba-ec4a-4d46-9846-ecc305ec36fb | B10: ="buggy" -> buggy | C10: ="inconclusive" -> inconclusive | D10: ="Claude Sonnet 4.6" -> Claude Sonnet 4.6 | E10: ="2026-10-12" -> 2026-10-12 | F10: =11250 -> 11250 | G10: =323 -> 323 | H10: =17.465 -> 17.465 | I10: ="" | J10: ="Unknown" -> Unknown | K10: ="Unknown" -> Unknown | L10: ="70582bba-ec4a-4d46-9846-ecc305ec36fb: model-usage.json; verification.json; control-verification.json; report.md" -> 70582bba-ec4a-4d46-9846-ecc305ec36fb: model-usage.json; verification.json; control-verification.json; report.md | M10: ="Claude Sonnet 4.6" -> Claude Sonnet 4.6 | N10: ="All recorded transport responses, including invalid responses" -> All recorded transport responses, including invalid responses | O10: =1 -> 1 | P10: =IF('All 17 saved engineering invest'!I10="",0,1) -> 0
A11: 6348e730-4d90-4e40-a3e7-6186a2825ca6 | B11: ="buggy" -> buggy | C11: ="inconclusive" -> inconclusive | D11: ="Claude Sonnet 4.6" -> Claude Sonnet 4.6 | E11: ="2026-10-12" -> 2026-10-12 | F11: =11322 -> 11322 | G11: =293 -> 293 | H11: =12.773 -> 12.773 | I11: ="" | J11: ="Unknown" -> Unknown | K11: ="Unknown" -> Unknown | L11: ="6348e730-4d90-4e40-a3e7-6186a2825ca6: model-usage.json; verification.json; control-verification.json; report.md" -> 6348e730-4d90-4e40-a3e7-6186a2825ca6: model-usage.json; verification.json; control-verification.json; report.md | M11: ="Claude Sonnet 4.6" -> Claude Sonnet 4.6 | N11: ="All recorded transport responses, including invalid responses" -> All recorded transport responses, including invalid responses | O11: =1 -> 1 | P11: =IF('All 17 saved engineering invest'!I11="",0,1) -> 0
A12: 88928c9e-85d5-4806-a8e0-69d59f27790d | B12: ="buggy" -> buggy | C12: ="inconclusive" -> inconclusive | D12: ="Claude Sonnet 4.6" -> Claude Sonnet 4.6 | E12: ="2026-10-12" -> 2026-10-12 | F12: =11276 -> 11276 | G12: =339 -> 339 | H12: =12.749 -> 12.749 | I12: ="" | J12: ="Unknown" -> Unknown | K12: ="Unknown" -> Unknown | L12: ="88928c9e-85d5-4806-a8e0-69d59f27790d: model-usage.json; verification.json; control-verification.json; report.md" -> 88928c9e-85d5-4806-a8e0-69d59f27790d: model-usage.json; verification.json; control-verification.json; report.md | M12: ="Claude Sonnet 4.6" -> Claude Sonnet 4.6 | N12: ="All recorded transport responses, including invalid responses" -> All recorded transport responses, including invalid responses | O12: =1 -> 1 | P12: =IF('All 17 saved engineering invest'!I12="",0,1) -> 0
A13: 9bf6f448-a6f3-43a7-9378-93602e6c7dbb | B13: ="fixed" -> fixed | C13: ="inconclusive" -> inconclusive | D13: ="Claude Sonnet 4.6" -> Claude Sonnet 4.6 | E13: ="2026-10-12" -> 2026-10-12 | F13: =11208 -> 11208 | G13: =261 -> 261 | H13: =12.679 -> 12.679 | I13: ="" | J13: ="Unknown" -> Unknown | K13: ="Unknown" -> Unknown | L13: ="9bf6f448-a6f3-43a7-9378-93602e6c7dbb: model-usage.json; verification.json; control-verification.json; report.md" -> 9bf6f448-a6f3-43a7-9378-93602e6c7dbb: model-usage.json; verification.json; control-verification.json; report.md | M13: ="Claude Sonnet 4.6" -> Claude Sonnet 4.6 | N13: ="All recorded transport responses, including invalid responses" -> All recorded transport responses, including invalid responses | O13: =1 -> 1 | P13: =IF('All 17 saved engineering invest'!I13="",0,1) -> 0
A14: 5a3547da-c82d-4847-b67e-3985407c7fe3 | B14: ="buggy" -> buggy | C14: ="inconclusive" -> inconclusive | D14: ="Claude Sonnet 4.6" -> Claude Sonnet 4.6 | E14: ="2026-10-12" -> 2026-10-12 | F14: =26994 -> 26994 | G14: =767 -> 767 | H14: =25.978 -> 25.978 | I14: ="" | J14: ="Unknown" -> Unknown | K14: ="Unknown" -> Unknown | L14: ="5a3547da-c82d-4847-b67e-3985407c7fe3: model-usage.json; verification.json; control-verification.json; report.md" -> 5a3547da-c82d-4847-b67e-3985407c7fe3: model-usage.json; verification.json; control-verification.json; report.md | M14: ="Claude Sonnet 4.6" -> Claude Sonnet 4.6 | N14: ="All recorded transport responses, including invalid responses" -> All recorded transport responses, including invalid responses | O14: =1 -> 1 | P14: =IF('All 17 saved engineering invest'!I14="",0,1) -> 0
A15: 5e7c759d-aedf-4102-b17c-a5f3ecff5104 | B15: ="buggy" -> buggy | C15: ="not_reproduced" -> not_reproduced | D15: ="Claude Sonnet 4.6" -> Claude Sonnet 4.6 | E15: ="2026-10-12" -> 2026-10-12 | F15: =65169 -> 65169 | G15: =2195 -> 2195 | H15: =60.974 -> 60.974 | I15: ="" | J15: ="Unknown" -> Unknown | K15: ="Unknown" -> Unknown | L15: ="5e7c759d-aedf-4102-b17c-a5f3ecff5104: model-usage.json; verification.json; control-verification.json; report.md" -> 5e7c759d-aedf-4102-b17c-a5f3ecff5104: model-usage.json; verification.json; control-verification.json; report.md | M15: ="Claude Sonnet 4.6" -> Claude Sonnet 4.6 | N15: ="All recorded transport responses, including invalid responses" -> All recorded transport responses, including invalid responses | O15: =1 -> 1 | P15: =IF('All 17 saved engineering invest'!I15="",0,1) -> 0
A16: 19ecc208-aa4c-47ce-bc92-5e3523dfae59 | B16: ="buggy" -> buggy | C16: ="not_reproduced" -> not_reproduced | D16: ="Claude Sonnet 4.6" -> Claude Sonnet 4.6 | E16: ="2026-10-12" -> 2026-10-12 | F16: =115544 -> 115544 | G16: =2605 -> 2605 | H16: =86.806 -> 86.806 | I16: ="" | J16: ="Unknown" -> Unknown | K16: ="Unknown" -> Unknown | L16: ="19ecc208-aa4c-47ce-bc92-5e3523dfae59: model-usage.json; verification.json; control-verification.json; report.md" -> 19ecc208-aa4c-47ce-bc92-5e3523dfae59: model-usage.json; verification.json; control-verification.json; report.md | M16: ="Claude Sonnet 4.6" -> Claude Sonnet 4.6 | N16: ="All recorded transport responses, including invalid responses" -> All recorded transport responses, including invalid responses | O16: =1 -> 1 | P16: =IF('All 17 saved engineering invest'!I16="",0,1) -> 0
A17: c4010a11-3341-416c-a863-52aff89893a5 | B17: ="fixed" -> fixed | C17: ="inconclusive" -> inconclusive | D17: ="Claude Sonnet 4.6" -> Claude Sonnet 4.6 | E17: ="2026-10-12" -> 2026-10-12 | F17: =18847 -> 18847 | G17: =599 -> 599 | H17: =19.171 -> 19.171 | I17: ="" | J17: ="Unknown" -> Unknown | K17: ="Unknown" -> Unknown | L17: ="c4010a11-3341-416c-a863-52aff89893a5: model-usage.json; verification.json; control-verification.json; report.md" -> c4010a11-3341-416c-a863-52aff89893a5: model-usage.json; verification.json; control-verification.json; report.md | M17: ="Claude Sonnet 4.6" -> Claude Sonnet 4.6 | N17: ="All recorded transport responses, including invalid responses" -> All recorded transport responses, including invalid responses | O17: =1 -> 1 | P17: =IF('All 17 saved engineering invest'!I17="",0,1) -> 0
A18: 247e9123-b7aa-46d6-9f36-936a6531960e | B18: ="buggy" -> buggy | C18: ="not_reproduced" -> not_reproduced | D18: ="Claude Sonnet 4.6" -> Claude Sonnet 4.6 | E18: ="2026-10-12" -> 2026-10-12 | F18: =60315 -> 60315 | G18: =2220 -> 2220 | H18: =63.924 -> 63.924 | I18: =0.2356695 -> 0.2356695 | J18: ="Complete x-litellm-response-cost coverage" -> Complete x-litellm-response-cost coverage | K18: ="2b541b20a97ef3df4261529bd48089792e01f2af" -> 2b541b20a97ef3df4261529bd48089792e01f2af | L18: ="247e9123-b7aa-46d6-9f36-936a6531960e: model-usage.json; verification.json; control-verification.json; report.md" -> 247e9123-b7aa-46d6-9f36-936a6531960e: model-usage.json; verification.json; control-verification.json; report.md | M18: ="Claude Sonnet 4.6" -> Claude Sonnet 4.6 | N18: ="All recorded transport responses, including invalid responses" -> All recorded transport responses, including invalid responses | O18: =1 -> 1 | P18: =IF('All 17 saved engineering invest'!I18="",0,1) -> 1
A19: b8ffd757-6aed-405d-b7ac-ed3b1c4d9236 | B19: ="buggy" -> buggy | C19: ="bug_confirmed" -> bug_confirmed | D19: ="Claude Sonnet 4.6" -> Claude Sonnet 4.6 | E19: ="2026-10-12" -> 2026-10-12 | F19: =41069 -> 41069 | G19: =1261 -> 1261 | H19: =51.651 -> 51.651 | I19: =0.1563342 -> 0.1563342 | J19: ="Complete x-litellm-response-cost coverage" -> Complete x-litellm-response-cost coverage | K19: ="2b541b20a97ef3df4261529bd48089792e01f2af" -> 2b541b20a97ef3df4261529bd48089792e01f2af | L19: ="b8ffd757-6aed-405d-b7ac-ed3b1c4d9236: model-usage.json; verification.json; control-verification.json; report.md" -> b8ffd757-6aed-405d-b7ac-ed3b1c4d9236: model-usage.json; verification.json; control-verification.json; report.md | M19: ="Claude Sonnet 4.6" -> Claude Sonnet 4.6 | N19: ="All recorded transport responses, including invalid responses" -> All recorded transport responses, including invalid responses | O19: =1 -> 1 | P19: =IF('All 17 saved engineering invest'!I19="",0,1) -> 1
A20: 7c259071-2c8c-45ee-8c65-5fafa1395ae7 | B20: ="buggy" -> buggy | C20: ="not_reproduced" -> not_reproduced | D20: ="Claude Sonnet 4.6" -> Claude Sonnet 4.6 | E20: ="2026-10-12" -> 2026-10-12 | F20: =64690 -> 64690 | G20: =2245 -> 2245 | H20: =64.727 -> 64.727 | I20: =0.2505195 -> 0.2505195 | J20: ="Complete x-litellm-response-cost coverage" -> Complete x-litellm-response-cost coverage | K20: ="2b541b20a97ef3df4261529bd48089792e01f2af" -> 2b541b20a97ef3df4261529bd48089792e01f2af | L20: ="7c259071-2c8c-45ee-8c65-5fafa1395ae7: model-usage.json; verification.json; control-verification.json; report.md" -> 7c259071-2c8c-45ee-8c65-5fafa1395ae7: model-usage.json; verification.json; control-verification.json; report.md | M20: ="Claude Sonnet 4.6" -> Claude Sonnet 4.6 | N20: ="All recorded transport responses, including invalid responses" -> All recorded transport responses, including invalid responses | O20: =1 -> 1 | P20: =IF('All 17 saved engineering invest'!I20="",0,1) -> 1
A21: 6d85b46a-df25-42a9-abe9-54978f07d964 | B21: ="fixed" -> fixed | C21: ="not_reproduced" -> not_reproduced | D21: ="Claude Sonnet 4.6" -> Claude Sonnet 4.6 | E21: ="2026-10-12" -> 2026-10-12 | F21: =82219 -> 82219 | G21: =2476 -> 2476 | H21: =73.639 -> 73.639 | I21: =0.3121767 -> 0.3121767 | J21: ="Complete x-litellm-response-cost coverage" -> Complete x-litellm-response-cost coverage | K21: ="2b541b20a97ef3df4261529bd48089792e01f2af" -> 2b541b20a97ef3df4261529bd48089792e01f2af | L21: ="6d85b46a-df25-42a9-abe9-54978f07d964: model-usage.json; verification.json; control-verification.json; report.md" -> 6d85b46a-df25-42a9-abe9-54978f07d964: model-usage.json; verification.json; control-verification.json; report.md | M21: ="Claude Sonnet 4.6" -> Claude Sonnet 4.6 | N21: ="All recorded transport responses, including invalid responses" -> All recorded transport responses, including invalid responses | O21: =1 -> 1 | P21: =IF('All 17 saved engineering invest'!I21="",0,1) -> 1

Sheet Two successful model smoke call
A1: Two successful model smoke calls
A2: Observed engineering evidence — 2026-10-12 · Main Scenario
A4: Variable / dimension | B4: Engineering smoke model | C4: Engineering smoke input tokens | D4: Engineering smoke output tokens | E4: Engineering smoke configured non-cache estimate USD | F4: Engineering smoke header accounting USD | G4: Engineering smoke duration seconds | H4: Engineering smoke cash invoice USD | I4: Engineering smoke unsupported-field status | J4: Engineering smoke result
A5: 2026-10-11T18:07:47.476Z | B5: ="claude-sonnet-4.6" -> claude-sonnet-4.6 | C5: =133 -> 133 | D5: =20 -> 20 | E5: =0.0007689 -> 0.0007689 | F5: ="" | G5: ="" | H5: ="" | I5: ="Unknown" -> Unknown | J5: ="successful model smoke call" -> successful model smoke call
A6: 2026-10-12T15:00:41.009Z | B6: ="claude-sonnet-4.6" -> claude-sonnet-4.6 | C6: =133 -> 133 | D6: =20 -> 20 | E6: =0.0007689 -> 0.0007689 | F6: ="" | G6: ="" | H6: ="" | I6: ="Unknown" -> Unknown | J6: ="successful model smoke call" -> successful model smoke call

Sheet Five rejected Bedrock access pr
A1: Five rejected Bedrock access probes — aggregate evidence
A2: Observed engineering evidence — 2026-10-12 · Main Scenario
A4: Variable / dimension | B4: Engineering probe count | C4: Engineering probe outcome | D4: Engineering probe tokens | E4: Engineering probe billing USD | F4: Engineering probe cash charges USD | G4: Engineering probe coverage note
A5: Rejected Bedrock access probes | B5: =5 -> 5 | C5: ="Rejected access / HTTP 403" -> Rejected access / HTTP 403 | D5: ="Unknown" -> Unknown | E5: ="" | F5: ="" | G5: ="Five probes retained as an aggregate; per-probe IDs, tokens and bills were not supplied. A 403 is not proof of zero cost." -> Five probes retained as an aggregate; per-probe IDs, tokens and bills were not supplied. A 403 is not proof of zero cost.

Sheet Observed gateway rate metadata
A1: Observed gateway rate metadata — not historical pricing
A2: Observed engineering evidence — 2026-10-12 · Main Scenario
A4: Variable / dimension | B4: Value
A5: Engineering current ordinary input USD per million | B5: =3.3 -> 3.3
A6: Engineering current ordinary output USD per million | B6: =16.5 -> 16.5
A7: Engineering current cache-read USD per million | B7: =0.33 -> 0.33
A8: Engineering current cache-write USD per million | B8: =4.125 -> 4.125
A9: Engineering original planning ceiling USD per run | B9: =0.1293 -> 0.1293
A10: Engineering gateway metadata observed UTC | B10: ="2026-10-12T15:16:59.061Z" -> 2026-10-12T15:16:59.061Z
A11: Engineering gateway metadata source file | B11: ="artifacts/tooling/litellm-cost-source-1791818219062.json" -> artifacts/tooling/litellm-cost-source-1791818219062.json
A12: Engineering historical rate and cache-category status | B12: ="Unknown" -> Unknown

Sheet Engineering costs — observed su
A1: Engineering costs — observed subset, conditional estimates and Unknown totals
A2: Observed engineering evidence — 2026-10-12 · Main Scenario
A4: Variable / dimension | B4: Value
A5: Engineering saved investigation count | B5: =SUM('All 17 saved engineering invest'!O5,'All 17 saved engineering invest'!O6,'All 17 saved engineering invest'!O7,'All 17 saved engineering invest'!O8,'All 17 saved engineering invest'!O9,'All 17 saved engineering invest'!O10,'All 17 saved engineering invest'!O11,'All 17 saved engineering invest'!O12,'All 17 saved engineering invest'!O13,'All 17 saved engineering invest'!O14,'All 17 saved engineering invest'!O15,'All 17 saved engineering invest'!O16,'All 17 saved engineering invest'!O17,'All 17 saved engineering invest'!O18,'All 17 saved engineering invest'!O19,'All 17 saved engineering invest'!O20,'All 17 saved engineering invest'!O21) -> 17
A6: Engineering accounted input-token subtotal | B6: =SUM('All 17 saved engineering invest'!F5,'All 17 saved engineering invest'!F6,'All 17 saved engineering invest'!F7,'All 17 saved engineering invest'!F8,'All 17 saved engineering invest'!F9,'All 17 saved engineering invest'!F10,'All 17 saved engineering invest'!F11,'All 17 saved engineering invest'!F12,'All 17 saved engineering invest'!F13,'All 17 saved engineering invest'!F14,'All 17 saved engineering invest'!F15,'All 17 saved engineering invest'!F16,'All 17 saved engineering invest'!F17,'All 17 saved engineering invest'!F18,'All 17 saved engineering invest'!F19,'All 17 saved engineering invest'!F20,'All 17 saved engineering invest'!F21) -> 556919
A7: Engineering accounted output-token subtotal | B7: =SUM('All 17 saved engineering invest'!G5,'All 17 saved engineering invest'!G6,'All 17 saved engineering invest'!G7,'All 17 saved engineering invest'!G8,'All 17 saved engineering invest'!G9,'All 17 saved engineering invest'!G10,'All 17 saved engineering invest'!G11,'All 17 saved engineering invest'!G12,'All 17 saved engineering invest'!G13,'All 17 saved engineering invest'!G14,'All 17 saved engineering invest'!G15,'All 17 saved engineering invest'!G16,'All 17 saved engineering invest'!G17,'All 17 saved engineering invest'!G18,'All 17 saved engineering invest'!G19,'All 17 saved engineering invest'!G20,'All 17 saved engineering invest'!G21) -> 16881
A8: Engineering complete-header investigation count | B8: =SUM('All 17 saved engineering invest'!P5,'All 17 saved engineering invest'!P6,'All 17 saved engineering invest'!P7,'All 17 saved engineering invest'!P8,'All 17 saved engineering invest'!P9,'All 17 saved engineering invest'!P10,'All 17 saved engineering invest'!P11,'All 17 saved engineering invest'!P12,'All 17 saved engineering invest'!P13,'All 17 saved engineering invest'!P14,'All 17 saved engineering invest'!P15,'All 17 saved engineering invest'!P16,'All 17 saved engineering invest'!P17,'All 17 saved engineering invest'!P18,'All 17 saved engineering invest'!P19,'All 17 saved engineering invest'!P20,'All 17 saved engineering invest'!P21) -> 4
A9: Engineering unknown-header investigation count | B9: ='Engineering costs — observed su'!B5-'Engineering costs — observed su'!B8 -> 13
A10: Engineering latest four gateway accounting subtotal USD | B10: =SUM('All 17 saved engineering invest'!I5,'All 17 saved engineering invest'!I6,'All 17 saved engineering invest'!I7,'All 17 saved engineering invest'!I8,'All 17 saved engineering invest'!I9,'All 17 saved engineering invest'!I10,'All 17 saved engineering invest'!I11,'All 17 saved engineering invest'!I12,'All 17 saved engineering invest'!I13,'All 17 saved engineering invest'!I14,'All 17 saved engineering invest'!I15,'All 17 saved engineering invest'!I16,'All 17 saved engineering invest'!I17,'All 17 saved engineering invest'!I18,'All 17 saved engineering invest'!I19,'All 17 saved engineering invest'!I20,'All 17 saved engineering invest'!I21) -> 0.9546999
A11: Engineering latest four mean gateway accounting USD per attempt | B11: ='Engineering costs — observed su'!B10/'Engineering costs — observed su'!B8 -> 0.23867497
A12: Engineering selected confirmed-run gateway accounting USD | B12: =IF('All 17 saved engineering invest'!I19="","",'All 17 saved engineering invest'!I19) -> 0.1563342
A13: Engineering conditional ordinary-rate investigation estimate USD | B13: =('Engineering costs — observed su'!B6*'Observed gateway rate metadata'!B5+'Engineering costs — observed su'!B7*'Observed gateway rate metadata'!B6)/1000000 -> 2.1163692
A14: Engineering conditional ordinary-rate estimate including smokes USD | B14: ='Engineering costs — observed su'!B13+SUM('Two successful model smoke call'!E5,'Two successful model smoke call'!E6) -> 2.117907
A15: Engineering complete project gateway accounting USD | B15: =""
A16: Engineering project cash invoice charges USD | B16: =""
A17: Engineering promotional credit deductions USD | B17: =""
A18: Engineering hosted browser cost USD | B18: =""
A19: Engineering storage cost USD | B19: =""
A20: Engineering coding subscription cost USD | B20: =""
A21: Engineering CFO subscription cost USD | B21: =""
A22: Engineering all-in commercial cost USD | B22: =""
A23: Engineering unknown cost-field status | B23: ="Unknown" -> Unknown

Sheet Model inputs
A1: Model inputs
A2: Integration values are aggregated snapshots; raw source records are not included.
A4: Variables
A5: Variable / segment | B5: Value
A6: Engineering accounted header record | B6: =IF('Model inputs'!B45="",0,1) -> 0
A7: Engineering accounted header record > 19ecc208-aa4c-47ce-bc92-5e3523dfae59 | B7: =IF('Model inputs'!B46="",0,1) -> 0
A8: Engineering accounted header record > 247e9123-b7aa-46d6-9f36-936a6531960e | B8: =IF('Model inputs'!B47="",0,1) -> 1
A9: Engineering accounted header record > 39b9bed4-fca9-4884-a7b9-3035fc860685 | B9: =IF('Model inputs'!B48="",0,1) -> 0
A10: Engineering accounted header record > 5a3547da-c82d-4847-b67e-3985407c7fe3 | B10: =IF('Model inputs'!B49="",0,1) -> 0
A11: Engineering accounted header record > 5e7c759d-aedf-4102-b17c-a5f3ecff5104 | B11: =IF('Model inputs'!B50="",0,1) -> 0
A12: Engineering accounted header record > 6348e730-4d90-4e40-a3e7-6186a2825ca6 | B12: =IF('Model inputs'!B51="",0,1) -> 0
A13: Engineering accounted header record > 66349e06-fc57-4de9-836f-b0a0d7ca0584 | B13: =IF('Model inputs'!B52="",0,1) -> 0
A14: Engineering accounted header record > 6992fe74-3395-430a-95ab-d73c207d70b6 | B14: =IF('Model inputs'!B53="",0,1) -> 0
A15: Engineering accounted header record > 6d85b46a-df25-42a9-abe9-54978f07d964 | B15: =IF('Model inputs'!B54="",0,1) -> 1
A16: Engineering accounted header record > 70582bba-ec4a-4d46-9846-ecc305ec36fb | B16: =IF('Model inputs'!B55="",0,1) -> 0
A17: Engineering accounted header record > 7c259071-2c8c-45ee-8c65-5fafa1395ae7 | B17: =IF('Model inputs'!B56="",0,1) -> 1
... A23: Engineering accounted header record > e07bdfa3-c839-4e68-b784-640244403b2c | B23: =IF('Model inputs'!B62="",0,1) -> 0
A24: Engineering smoke configured non-cache estimate USD | B24: =""
A25: Engineering smoke configured non-cache estimate USD > 2026-10-11T18:07:47.476Z | B25: ='Two successful model smoke call'!E5 -> 0.0007689
A26: Engineering smoke configured non-cache estimate USD > 2026-10-12T15:00:41.009Z | B26: ='Two successful model smoke call'!E6 -> 0.0007689
A27: Engineering output tokens | B27: =""
A28: Engineering output tokens > 19ecc208-aa4c-47ce-bc92-5e3523dfae59 | B28: ='All 17 saved engineering invest'!G16 -> 2605
A29: Engineering output tokens > 247e9123-b7aa-46d6-9f36-936a6531960e | B29: ='All 17 saved engineering invest'!G18 -> 2220
A30: Engineering output tokens > 39b9bed4-fca9-4884-a7b9-3035fc860685 | B30: ='All 17 saved engineering invest'!G9 -> 268
A31: Engineering output tokens > 5a3547da-c82d-4847-b67e-3985407c7fe3 | B31: ='All 17 saved engineering invest'!G14 -> 767
A32: Engineering output tokens > 5e7c759d-aedf-4102-b17c-a5f3ecff5104 | B32: ='All 17 saved engineering invest'!G15 -> 2195
A33: Engineering output tokens > 6348e730-4d90-4e40-a3e7-6186a2825ca6 | B33: ='All 17 saved engineering invest'!G11 -> 293
A34: Engineering output tokens > 66349e06-fc57-4de9-836f-b0a0d7ca0584 | B34: =""
A35: Engineering output tokens > 6992fe74-3395-430a-95ab-d73c207d70b6 | B35: ='All 17 saved engineering invest'!G7 -> 328
A36: Engineering output tokens > 6d85b46a-df25-42a9-abe9-54978f07d964 | B36: ='All 17 saved engineering invest'!G21 -> 2476
A37: Engineering output tokens > 70582bba-ec4a-4d46-9846-ecc305ec36fb | B37: ='All 17 saved engineering invest'!G10 -> 323
A38: Engineering output tokens > 7c259071-2c8c-45ee-8c65-5fafa1395ae7 | B38: ='All 17 saved engineering invest'!G20 -> 2245
A39: Engineering output tokens > 7e60e53a-1a02-4f81-918d-24649030fae0 | B39: ='All 17 saved engineering invest'!G8 -> 310
A40: Engineering output tokens > 88928c9e-85d5-4806-a8e0-69d59f27790d | B40: ='All 17 saved engineering invest'!G12 -> 339
A41: Engineering output tokens > 9bf6f448-a6f3-43a7-9378-93602e6c7dbb | B41: ='All 17 saved engineering invest'!G13 -> 261
A42: Engineering output tokens > b8ffd757-6aed-405d-b7ac-ed3b1c4d9236 | B42: ='All 17 saved engineering invest'!G19 -> 1261
A43: Engineering output tokens > c4010a11-3341-416c-a863-52aff89893a5 | B43: ='All 17 saved engineering invest'!G17 -> 599
A44: Engineering output tokens > e07bdfa3-c839-4e68-b784-640244403b2c | B44: ='All 17 saved engineering invest'!G6 -> 391
A45: Engineering response-header gateway accounting USD | B45: =""
A46: Engineering response-header gateway accounting USD > 19ecc208-aa4c-47ce-bc92-5e3523dfae59 | B46: =""
...
